#VRML_SIM R2020a utf8
WorldInfo {
}
Viewpoint {
  orientation -0.12331490699730725 0.9746480052978808 0.18669413349408634 1.964645941613898
  position 0.342892930028144 0.20820965306786876 -0.1331342092756838
}
TexturedBackground {
}
TexturedBackgroundLight {
}
RectangleArena {
}
Robot {
  translation 0 0.07 0
  children [
    DEF BODY Solid {
      children [
        DEF G0 Group {
          children [
            Shape {
              appearance PBRAppearance {
                metalness 0.4
              }
              geometry Box {
                size 0.07 0.03 0.12
              }
            }
            Transform {
              translation 0 -0.018 -0.045
              children [
                Shape {
                  appearance PBRAppearance {
                  }
                  geometry Sphere {
                    radius 0.007
                    subdivision 2
                  }
                }
              ]
            }
            Transform {
              translation 0 -0.015 -0.045
              children [
                Shape {
                  appearance PBRAppearance {
                  }
                  geometry Cylinder {
                    height 0.009
                    radius 0.008
                  }
                }
              ]
            }
          ]
        }
      ]
      name "solid(2)"
      boundingObject USE G0
    }
    HingeJoint {
      jointParameters HingeJointParameters {
        anchor 0.055 0 0.04
      }
      device [
        RotationalMotor {
          name "wheel_right"
        }
      ]
      endPoint DEF WHEEL_RIGHT Solid {
        translation 0.055 0 0.04
        rotation 0 0 1 1.5708003061004252
        children [
          DEF WHEEL Shape {
            appearance PBRAppearance {
              baseColor 0.145098 0.145098 0.145098
              metalness 0
            }
            geometry Cylinder {
              height 0.03
              radius 0.025
            }
          }
        ]
        boundingObject USE WHEEL
        physics DEF WHEEL_PH Physics {
        }
      }
    }
    HingeJoint {
      jointParameters HingeJointParameters {
        anchor -0.055 0 0.04
      }
      endPoint DEF WHEEL_LEFT Solid {
        translation -0.055 0 0.04
        rotation 0 0 1 1.5707996938995747
        children [
          USE WHEEL
        ]
        name "solid(1)"
        boundingObject USE WHEEL
        physics USE WHEEL_PH
      }
    }
  ]
  boundingObject USE G0
  physics Physics {
  }
}
